Traceback (most recent call last):
  File "/home/malavika/anaconda3/envs/cnn_env/lib/python3.10/site-packages/wandb/sdk/wandb_config.py", line 165, in __getattr__
    return self.__getitem__(key)
  File "/home/malavika/anaconda3/envs/cnn_env/lib/python3.10/site-packages/wandb/sdk/wandb_config.py", line 130, in __getitem__
    return self._items[key]
KeyError: 'wandb_project'

The above exception was the direct cause of the following exception:

Traceback (most recent call last):
  File "/home/malavika/da6401_assignment2/part-B-cnn_finetune/train.py", line 125, in wandb_sweep
    train(config, model, loss_fn, optimizer, scheduler, train_loader, val_loader, save_model=True)
  File "/home/malavika/da6401_assignment2/part-B-cnn_finetune/train.py", line 23, in train
    wandb.init(project=config.wandb_project, config=config)
  File "/home/malavika/anaconda3/envs/cnn_env/lib/python3.10/site-packages/wandb/sdk/wandb_config.py", line 167, in __getattr__
    raise AttributeError(
AttributeError: <class 'wandb.sdk.wandb_config.Config'> object has no attribute 'wandb_project'
